2024-06-23 03:03:54.284 WARNING (SyncWorker_0) [homeassistant.loader] We found a custom integration dahua_vto which has not been tested by Home Assistant. This component might cause stability problems, be sure to disable it if you experience issues with Home Assistant
2024-06-23 03:03:54.286 WARNING (SyncWorker_0) [homeassistant.loader] We found a custom integration hacs which has not been tested by Home Assistant. This component might cause stability problems, be sure to disable it if you experience issues with Home Assistant
2024-06-23 03:03:54.694 WARNING (MainThread) [homeassistant.helpers.translation] Failed to load integration for translation: Integration 'lets_encrypt' not found.
2024-06-23 03:03:54.697 WARNING (MainThread) [homeassistant.helpers.translation] Failed to load integration for translation: Integration 'aliases' not found.
2024-06-23 03:03:54.697 WARNING (MainThread) [homeassistant.helpers.translation] Failed to load integration for translation: Integration 'domains' not found.
2024-06-23 03:03:54.697 WARNING (MainThread) [homeassistant.helpers.translation] Failed to load integration for translation: Integration 'token' not found.
2024-06-23 03:03:56.576 ERROR (MainThread) [homeassistant.config] Invalid config for 'sensor' from integration 'dahua_vto' at configuration.yaml, line 57: 'camera' is an invalid option for 'dahua_vto.sensor', check: camera, please check the docs at https://github.com/myhomeiot/DahuaVTO
2024-06-23 03:03:56.577 ERROR (MainThread) [homeassistant.config] Platform error: sensor - No module named 'homeassistant.components.ffmpeg.sensor'
Traceback (most recent call last):
  File "/usr/src/homeassistant/homeassistant/config.py", line 1440, in _async_load_and_validate_platform_integration
    platform = await p_integration.integration.async_get_platform(domain)
               ^^^^^^^^^^^^^^^^^^^^^^^^^^^^^^^^^^^^^^^^^^^^^^^^^^^^^^^^^^
  File "/usr/src/homeassistant/homeassistant/loader.py", line 1085, in async_get_platform
    platforms = await self.async_get_platforms((platform_name,))
                ^^^^^^^^^^^^^^^^^^^^^^^^^^^^^^^^^^^^^^^^^^^^^^^^
  File "/usr/src/homeassistant/homeassistant/loader.py", line 1162, in async_get_platforms
    import_future.result()
  File "/usr/src/homeassistant/homeassistant/loader.py", line 1132, in async_get_platforms
    await self.hass.async_add_import_executor_job(
  File "/usr/local/lib/python3.12/concurrent/futures/thread.py", line 58, in run
    result = self.fn(*self.args, **self.kwargs)
             ^^^^^^^^^^^^^^^^^^^^^^^^^^^^^^^^^^
  File "/usr/src/homeassistant/homeassistant/loader.py", line 1075, in _load_platforms
    platform_name: self._load_platform(platform_name)
                   ^^^^^^^^^^^^^^^^^^^^^^^^^^^^^^^^^^
  File "/usr/src/homeassistant/homeassistant/loader.py", line 1249, in _load_platform
    cache[full_name] = self._import_platform(platform_name)
                       ^^^^^^^^^^^^^^^^^^^^^^^^^^^^^^^^^^^^
  File "/usr/src/homeassistant/homeassistant/loader.py", line 1281, in _import_platform
    return importlib.import_module(f"{self.pkg_path}.{platform_name}")
           ^^^^^^^^^^^^^^^^^^^^^^^^^^^^^^^^^^^^^^^^^^^^^^^^^^^^^^^^^^^
  File "/usr/src/homeassistant/homeassistant/util/loop.py", line 131, in protected_loop_func
    return func(*args, **kwargs)
           ^^^^^^^^^^^^^^^^^^^^^
  File "/usr/local/lib/python3.12/importlib/__init__.py", line 90, in import_module
    return _bootstrap._gcd_import(name[level:], package, level)
           ^^^^^^^^^^^^^^^^^^^^^^^^^^^^^^^^^^^^^^^^^^^^^^^^^^^^
  File "<frozen importlib._bootstrap>", line 1387, in _gcd_import
  File "<frozen importlib._bootstrap>", line 1360, in _find_and_load
  File "<frozen importlib._bootstrap>", line 1324, in _find_and_load_unlocked
ModuleNotFoundError: No module named 'homeassistant.components.ffmpeg.sensor'
2024-06-23 03:03:56.710 ERROR (MainThread) [homeassistant.setup] Setup failed for 'token': Integration not found.
2024-06-23 03:03:56.711 ERROR (MainThread) [homeassistant.setup] Setup failed for 'lets_encrypt': Integration not found.
2024-06-23 03:03:56.711 ERROR (MainThread) [homeassistant.setup] Setup failed for 'aliases': Integration not found.
2024-06-23 03:03:56.711 ERROR (MainThread) [homeassistant.setup] Setup failed for 'domains': Integration not found.
2024-06-23 03:03:57.847 ERROR (MainThread) [homeassistant.config] Platform error: notify - No module named 'homeassistant.components.template.notify'
Traceback (most recent call last):
  File "/usr/src/homeassistant/homeassistant/config.py", line 1440, in _async_load_and_validate_platform_integration
    platform = await p_integration.integration.async_get_platform(domain)
               ^^^^^^^^^^^^^^^^^^^^^^^^^^^^^^^^^^^^^^^^^^^^^^^^^^^^^^^^^^
  File "/usr/src/homeassistant/homeassistant/loader.py", line 1085, in async_get_platform
    platforms = await self.async_get_platforms((platform_name,))
                ^^^^^^^^^^^^^^^^^^^^^^^^^^^^^^^^^^^^^^^^^^^^^^^^
  File "/usr/src/homeassistant/homeassistant/loader.py", line 1162, in async_get_platforms
    import_future.result()
  File "/usr/src/homeassistant/homeassistant/loader.py", line 1132, in async_get_platforms
    await self.hass.async_add_import_executor_job(
  File "/usr/local/lib/python3.12/concurrent/futures/thread.py", line 58, in run
    result = self.fn(*self.args, **self.kwargs)
             ^^^^^^^^^^^^^^^^^^^^^^^^^^^^^^^^^^
  File "/usr/src/homeassistant/homeassistant/loader.py", line 1075, in _load_platforms
    platform_name: self._load_platform(platform_name)
                   ^^^^^^^^^^^^^^^^^^^^^^^^^^^^^^^^^^
  File "/usr/src/homeassistant/homeassistant/loader.py", line 1249, in _load_platform
    cache[full_name] = self._import_platform(platform_name)
                       ^^^^^^^^^^^^^^^^^^^^^^^^^^^^^^^^^^^^
  File "/usr/src/homeassistant/homeassistant/loader.py", line 1281, in _import_platform
    return importlib.import_module(f"{self.pkg_path}.{platform_name}")
           ^^^^^^^^^^^^^^^^^^^^^^^^^^^^^^^^^^^^^^^^^^^^^^^^^^^^^^^^^^^
  File "/usr/src/homeassistant/homeassistant/util/loop.py", line 131, in protected_loop_func
    return func(*args, **kwargs)
           ^^^^^^^^^^^^^^^^^^^^^
  File "/usr/local/lib/python3.12/importlib/__init__.py", line 90, in import_module
    return _bootstrap._gcd_import(name[level:], package, level)
           ^^^^^^^^^^^^^^^^^^^^^^^^^^^^^^^^^^^^^^^^^^^^^^^^^^^^
  File "<frozen importlib._bootstrap>", line 1387, in _gcd_import
  File "<frozen importlib._bootstrap>", line 1360, in _find_and_load
  File "<frozen importlib._bootstrap>", line 1324, in _find_and_load_unlocked
ModuleNotFoundError: No module named 'homeassistant.components.template.notify'
2024-06-23 03:03:58.315 ERROR (MainThread) [homeassistant.config] Invalid config for 'shelly' at configuration.yaml, line 42: 'devices' is an invalid option for 'shelly', check: shelly->devices, please check the docs at https://www.home-assistant.io/integrations/shelly
2024-06-23 03:03:58.315 ERROR (MainThread) [homeassistant.setup] Setup failed for 'shelly': Invalid config.
2024-06-23 03:03:59.294 WARNING (MainThread) [homeassistant.helpers.frame] Detected that custom integration 'hacs' accesses hass.components.frontend. This is deprecated and will stop working in Home Assistant 2024.9, it should be updated to import functions used from frontend directly at custom_components/hacs/frontend.py, line 68: hass.components.frontend.async_register_built_in_panel(, please create a bug report at https://github.com/hacs/integration/issues
2024-06-23 03:04:01.333 ERROR (MainThread) [homeassistant.components.automation] Automation with alias 'New automation' could not be validated and has been disabled: extra keys not allowed @ data['automation']. Got [{'alias': 'Dahua VTO Call Notification', 'trigger': {'platform': 'event', 'event_type': 'dahua_vto', 'event_data': {'Code': 'BackKeyLight'}}, 'action': [{'service': 'camera.snapshot', 'data': {'entity_id': 'camera.dahua_vto', 'filename': '/config/www/snapshot.jpg'}}, {'delay': '00:00:02'}, {'service': 'notify.telegram', 'data': {'message': 'Cineva e la poarta!', 'data': {'photo': [{'file': '/config/www/snapshot.jpg', 'caption': 'Snapshot from Dahua VTO'}]}}}]}]
2024-06-23 03:04:02.942 WARNING (MainThread) [homeassistant.helpers.frame] Detected that custom integration 'hacs' accesses hass.helpers.event. This is deprecated and will stop working in Home Assistant 2024.11, it should be updated to import functions used from event directly at custom_components/hacs/base.py, line 642: self.hass.helpers.event.async_track_time_interval(, please create a bug report at https://github.com/hacs/integration/issues
2024-06-23 03:53:27.996 ERROR (MainThread) [telegram.ext.Updater] Error while getting Updates: httpx.ReadError: 
2024-06-23 03:53:27.997 ERROR (MainThread) [telegram.ext.Updater] Exception happened while polling for updates.
Traceback (most recent call last):
  File "/usr/local/lib/python3.12/site-packages/httpx/_transports/default.py", line 69, in map_httpcore_exceptions
    yield
  File "/usr/local/lib/python3.12/site-packages/httpx/_transports/default.py", line 373, in handle_async_request
    resp = await self._pool.handle_async_request(req)
           ^^^^^^^^^^^^^^^^^^^^^^^^^^^^^^^^^^^^^^^^^^
  File "/usr/local/lib/python3.12/site-packages/httpcore/_async/connection_pool.py", line 216, in handle_async_request
    raise exc from None
  File "/usr/local/lib/python3.12/site-packages/httpcore/_async/connection_pool.py", line 196, in handle_async_request
    response = await connection.handle_async_request(
               ^^^^^^^^^^^^^^^^^^^^^^^^^^^^^^^^^^^^^^
  File "/usr/local/lib/python3.12/site-packages/httpcore/_async/connection.py", line 101, in handle_async_request
    return await self._connection.handle_async_request(request)
           ^^^^^^^^^^^^^^^^^^^^^^^^^^^^^^^^^^^^^^^^^^^^^^^^^^^^
  File "/usr/local/lib/python3.12/site-packages/httpcore/_async/http11.py", line 143, in handle_async_request
    raise exc
  File "/usr/local/lib/python3.12/site-packages/httpcore/_async/http11.py", line 113, in handle_async_request
    ) = await self._receive_response_headers(**kwargs)
        ^^^^^^^^^^^^^^^^^^^^^^^^^^^^^^^^^^^^^^^^^^^^^^
  File "/usr/local/lib/python3.12/site-packages/httpcore/_async/http11.py", line 186, in _receive_response_headers
    event = await self._receive_event(timeout=timeout)
            ^^^^^^^^^^^^^^^^^^^^^^^^^^^^^^^^^^^^^^^^^^
  File "/usr/local/lib/python3.12/site-packages/httpcore/_async/http11.py", line 224, in _receive_event
    data = await self._network_stream.read(
           ^^^^^^^^^^^^^^^^^^^^^^^^^^^^^^^^
  File "/usr/local/lib/python3.12/site-packages/httpcore/_backends/anyio.py", line 32, in read
    with map_exceptions(exc_map):
  File "/usr/local/lib/python3.12/contextlib.py", line 158, in __exit__
    self.gen.throw(value)
  File "/usr/local/lib/python3.12/site-packages/httpcore/_exceptions.py", line 14, in map_exceptions
    raise to_exc(exc) from exc
httpcore.ReadError

The above exception was the direct cause of the following exception:

Traceback (most recent call last):
  File "/usr/local/lib/python3.12/site-packages/telegram/request/_httpxrequest.py", line 276, in do_request
    res = await self._client.request(
          ^^^^^^^^^^^^^^^^^^^^^^^^^^^
  File "/usr/local/lib/python3.12/site-packages/httpx/_client.py", line 1574, in request
    return await self.send(request, auth=auth, follow_redirects=follow_redirects)
           ^^^^^^^^^^^^^^^^^^^^^^^^^^^^^^^^^^^^^^^^^^^^^^^^^^^^^^^^^^^^^^^^^^^^^^
  File "/usr/local/lib/python3.12/site-packages/httpx/_client.py", line 1661, in send
    response = await self._send_handling_auth(
               ^^^^^^^^^^^^^^^^^^^^^^^^^^^^^^^
  File "/usr/local/lib/python3.12/site-packages/httpx/_client.py", line 1689, in _send_handling_auth
    response = await self._send_handling_redirects(
               ^^^^^^^^^^^^^^^^^^^^^^^^^^^^^^^^^^^^
  File "/usr/local/lib/python3.12/site-packages/httpx/_client.py", line 1726, in _send_handling_redirects
    response = await self._send_single_request(request)
               ^^^^^^^^^^^^^^^^^^^^^^^^^^^^^^^^^^^^^^^^
  File "/usr/local/lib/python3.12/site-packages/httpx/_client.py", line 1763, in _send_single_request
    response = await transport.handle_async_request(request)
               ^^^^^^^^^^^^^^^^^^^^^^^^^^^^^^^^^^^^^^^^^^^^^
  File "/usr/local/lib/python3.12/site-packages/httpx/_transports/default.py", line 372, in handle_async_request
    with map_httpcore_exceptions():
  File "/usr/local/lib/python3.12/contextlib.py", line 158, in __exit__
    self.gen.throw(value)
  File "/usr/local/lib/python3.12/site-packages/httpx/_transports/default.py", line 86, in map_httpcore_exceptions
    raise mapped_exc(message) from exc
httpx.ReadError

The above exception was the direct cause of the following exception:

Traceback (most recent call last):
  File "/usr/local/lib/python3.12/site-packages/telegram/ext/_updater.py", line 742, in _network_loop_retry
    if not await do_action():
           ^^^^^^^^^^^^^^^^^
  File "/usr/local/lib/python3.12/site-packages/telegram/ext/_updater.py", line 736, in do_action
    return action_cb_task.result()
           ^^^^^^^^^^^^^^^^^^^^^^^
  File "/usr/local/lib/python3.12/site-packages/telegram/ext/_updater.py", line 387, in polling_action_cb
    raise exc
  File "/usr/local/lib/python3.12/site-packages/telegram/ext/_updater.py", line 376, in polling_action_cb
    updates = await self.bot.get_updates(
              ^^^^^^^^^^^^^^^^^^^^^^^^^^^
  File "/usr/local/lib/python3.12/site-packages/telegram/_bot.py", line 541, in decorator
    result = await func(self, *args, **kwargs)
             ^^^^^^^^^^^^^^^^^^^^^^^^^^^^^^^^^
  File "/usr/local/lib/python3.12/site-packages/telegram/_bot.py", line 4177, in get_updates
    await self._post(
  File "/usr/local/lib/python3.12/site-packages/telegram/_bot.py", line 629, in _post
    return await self._do_post(
           ^^^^^^^^^^^^^^^^^^^^
  File "/usr/local/lib/python3.12/site-packages/telegram/_bot.py", line 657, in _do_post
    return await request.post(
           ^^^^^^^^^^^^^^^^^^^
  File "/usr/local/lib/python3.12/site-packages/telegram/request/_baserequest.py", line 200, in post
    result = await self._request_wrapper(
             ^^^^^^^^^^^^^^^^^^^^^^^^^^^^
  File "/usr/local/lib/python3.12/site-packages/telegram/request/_baserequest.py", line 340, in _request_wrapper
    raise exc
  File "/usr/local/lib/python3.12/site-packages/telegram/request/_baserequest.py", line 330, in _request_wrapper
    code, payload = await self.do_request(
                    ^^^^^^^^^^^^^^^^^^^^^^
  File "/usr/local/lib/python3.12/site-packages/telegram/request/_httpxrequest.py", line 300, in do_request
    raise NetworkError(f"httpx.{err.__class__.__name__}: {err}") from err
telegram.error.NetworkError: httpx.ReadError: 
2024-06-23 12:13:41.432 ERROR (MainThread) [homeassistant.components.hassio.handler] Client error on /ingress/validate_session request 0, message='Attempt to decode JSON with unexpected mimetype: text/plain; charset=utf-8', url=URL('http://172.30.32.2/ingress/validate_session')
2024-06-23 12:13:41.433 ERROR (MainThread) [homeassistant.components.hassio] Failed to to call /ingress/validate_session - 
2024-06-23 20:51:42.881 ERROR (MainThread) [homeassistant.components.hassio.handler] Client error on /ingress/validate_session request 0, message='Attempt to decode JSON with unexpected mimetype: text/plain; charset=utf-8', url=URL('http://172.30.32.2/ingress/validate_session')
2024-06-23 20:51:42.882 ERROR (MainThread) [homeassistant.components.hassio] Failed to to call /ingress/validate_session - 
